<?xml version="1.0" encoding="UTF-8"?>
<testng-results skipped="0" failed="2" total="6" passed="4">
  <reporter-output>
  </reporter-output>
  <suite name="Surefire suite" duration-ms="47" started-at="2017-08-03T13:33:23Z" finished-at="2017-08-03T13:33:23Z">
    <groups>
    </groups>
    <test name="Surefire test" duration-ms="47" started-at="2017-08-03T13:33:23Z" finished-at="2017-08-03T13:33:23Z">
      <class name="factTestIT">
        <test-method status="FAIL" signature="testFact2()[pri:0, instance:factTestIT@8dacdf]" name="testFact2" duration-ms="0" started-at="2017-08-03T16:33:23Z" finished-at="2017-08-03T16:33:23Z">
          <exception class="java.lang.AssertionError">
            <message>
              <![CDATA[expected [119] but found [120]]]>
            </message>
            <full-stacktrace>
              <![CDATA[java.lang.AssertionError: expected [119] but found [120]
	at org.testng.Assert.fail(Assert.java:94)
	at org.testng.Assert.failNotEquals(Assert.java:494)
	at org.testng.Assert.assertEquals(Assert.java:123)
	at org.testng.Assert.assertEquals(Assert.java:265)
	at org.testng.Assert.assertEquals(Assert.java:275)
	at factTestIT.testFact2(factTestIT.java:32)
	at sun.reflect.NativeMethodAccessorImpl.invoke0(Native Method)
	at sun.reflect.NativeMethodAccessorImpl.invoke(NativeMethodAccessorImpl.java:62)
	at sun.reflect.DelegatingMethodAccessorImpl.invoke(DelegatingMethodAccessorImpl.java:43)
	at java.lang.reflect.Method.invoke(Method.java:498)
	at org.testng.internal.MethodInvocationHelper.invokeMethod(MethodInvocationHelper.java:80)
	at org.testng.internal.Invoker.invokeMethod(Invoker.java:714)
	at org.testng.internal.Invoker.invokeTestMethod(Invoker.java:901)
	at org.testng.internal.Invoker.invokeTestMethods(Invoker.java:1231)
	at org.testng.internal.TestMethodWorker.invokeTestMethods(TestMethodWorker.java:127)
	at org.testng.internal.TestMethodWorker.run(TestMethodWorker.java:111)
	at org.testng.TestRunner.privateRun(TestRunner.java:767)
	at org.testng.TestRunner.run(TestRunner.java:617)
	at org.testng.SuiteRunner.runTest(SuiteRunner.java:334)
	at org.testng.SuiteRunner.runSequentially(SuiteRunner.java:329)
	at org.testng.SuiteRunner.privateRun(SuiteRunner.java:291)
	at org.testng.SuiteRunner.run(SuiteRunner.java:240)
	at org.testng.SuiteRunnerWorker.runSuite(SuiteRunnerWorker.java:52)
	at org.testng.SuiteRunnerWorker.run(SuiteRunnerWorker.java:86)
	at org.testng.TestNG.runSuitesSequentially(TestNG.java:1198)
	at org.testng.TestNG.runSuitesLocally(TestNG.java:1123)
	at org.testng.TestNG.run(TestNG.java:1031)
	at org.apache.maven.surefire.testng.TestNGExecutor.run(TestNGExecutor.java:135)
	at org.apache.maven.surefire.testng.TestNGDirectoryTestSuite.executeMulti(TestNGDirectoryTestSuite.java:193)
	at org.apache.maven.surefire.testng.TestNGDirectoryTestSuite.execute(TestNGDirectoryTestSuite.java:94)
	at org.apache.maven.surefire.testng.TestNGProvider.invoke(TestNGProvider.java:146)
	at org.apache.maven.surefire.booter.ForkedBooter.invokeProviderInSameClassLoader(ForkedBooter.java:386)
	at org.apache.maven.surefire.booter.ForkedBooter.runSuitesInProcess(ForkedBooter.java:323)
	at org.apache.maven.surefire.booter.ForkedBooter.main(ForkedBooter.java:143)
]]>
            </full-stacktrace>
          </exception> <!-- java.lang.AssertionError -->
          <reporter-output>
          </reporter-output>
        </test-method> <!-- testFact2 -->
        <test-method status="PASS" signature="start()[pri:0, instance:factTestIT@8dacdf]" name="start" is-config="true" duration-ms="0" started-at="2017-08-03T16:33:23Z" finished-at="2017-08-03T16:33:23Z">
          <reporter-output>
          </reporter-output>
        </test-method> <!-- start -->
        <test-method status="PASS" signature="testFact1()[pri:0, instance:factTestIT@8dacdf]" name="testFact1" duration-ms="0" started-at="2017-08-03T16:33:23Z" finished-at="2017-08-03T16:33:23Z">
          <reporter-output>
          </reporter-output>
        </test-method> <!-- testFact1 -->
      </class> <!-- factTestIT -->
      <class name="AddTestIT">
        <test-method status="PASS" signature="init()[pri:0, instance:factTestIT@8dacdf]" name="init" is-config="true" duration-ms="0" started-at="2017-08-03T16:33:23Z" finished-at="2017-08-03T16:33:23Z">
          <reporter-output>
          </reporter-output>
        </test-method> <!-- init -->
        <test-method status="PASS" signature="setup()[pri:0, instance:AddTestIT@152f6e2]" name="setup" is-config="true" duration-ms="0" started-at="2017-08-03T16:33:23Z" finished-at="2017-08-03T16:33:23Z">
          <reporter-output>
          </reporter-output>
        </test-method> <!-- setup -->
        <test-method status="PASS" signature="testAdd1()[pri:0, instance:AddTestIT@152f6e2]" name="testAdd1" duration-ms="0" started-at="2017-08-03T16:33:23Z" finished-at="2017-08-03T16:33:23Z">
          <reporter-output>
          </reporter-output>
        </test-method> <!-- testAdd1 -->
        <test-method status="PASS" signature="testAdd1()[pri:0, instance:AddTestIT@152f6e2]" name="testAdd1" duration-ms="0" started-at="2017-08-03T16:33:23Z" finished-at="2017-08-03T16:33:23Z">
          <reporter-output>
          </reporter-output>
        </test-method> <!-- testAdd1 -->
        <test-method status="PASS" signature="start()[pri:0, instance:AddTestIT@152f6e2]" name="start" is-config="true" duration-ms="0" started-at="2017-08-03T16:33:23Z" finished-at="2017-08-03T16:33:23Z">
          <reporter-output>
          </reporter-output>
        </test-method> <!-- start -->
        <test-method status="PASS" signature="testAdd1()[pri:0, instance:AddTestIT@152f6e2]" name="testAdd1" duration-ms="0" started-at="2017-08-03T16:33:23Z" finished-at="2017-08-03T16:33:23Z">
          <reporter-output>
          </reporter-output>
        </test-method> <!-- testAdd1 -->
        <test-method status="FAIL" signature="testAdd2()[pri:0, instance:AddTestIT@152f6e2]" name="testAdd2" duration-ms="0" started-at="2017-08-03T16:33:23Z" finished-at="2017-08-03T16:33:23Z">
          <exception class="java.lang.AssertionError">
            <message>
              <![CDATA[expected [0] but found [-1]]]>
            </message>
            <full-stacktrace>
              <![CDATA[java.lang.AssertionError: expected [0] but found [-1]
	at org.testng.Assert.fail(Assert.java:94)
	at org.testng.Assert.failNotEquals(Assert.java:494)
	at org.testng.Assert.assertEquals(Assert.java:123)
	at org.testng.Assert.assertEquals(Assert.java:265)
	at org.testng.Assert.assertEquals(Assert.java:275)
	at AddTestIT.testAdd2(AddTestIT.java:35)
	at sun.reflect.NativeMethodAccessorImpl.invoke0(Native Method)
	at sun.reflect.NativeMethodAccessorImpl.invoke(NativeMethodAccessorImpl.java:62)
	at sun.reflect.DelegatingMethodAccessorImpl.invoke(DelegatingMethodAccessorImpl.java:43)
	at java.lang.reflect.Method.invoke(Method.java:498)
	at org.testng.internal.MethodInvocationHelper.invokeMethod(MethodInvocationHelper.java:80)
	at org.testng.internal.Invoker.invokeMethod(Invoker.java:714)
	at org.testng.internal.Invoker.invokeTestMethod(Invoker.java:901)
	at org.testng.internal.Invoker.invokeTestMethods(Invoker.java:1231)
	at org.testng.internal.TestMethodWorker.invokeTestMethods(TestMethodWorker.java:127)
	at org.testng.internal.TestMethodWorker.run(TestMethodWorker.java:111)
	at org.testng.TestRunner.privateRun(TestRunner.java:767)
	at org.testng.TestRunner.run(TestRunner.java:617)
	at org.testng.SuiteRunner.runTest(SuiteRunner.java:334)
	at org.testng.SuiteRunner.runSequentially(SuiteRunner.java:329)
	at org.testng.SuiteRunner.privateRun(SuiteRunner.java:291)
	at org.testng.SuiteRunner.run(SuiteRunner.java:240)
	at org.testng.SuiteRunnerWorker.runSuite(SuiteRunnerWorker.java:52)
	at org.testng.SuiteRunnerWorker.run(SuiteRunnerWorker.java:86)
	at org.testng.TestNG.runSuitesSequentially(TestNG.java:1198)
	at org.testng.TestNG.runSuitesLocally(TestNG.java:1123)
	at org.testng.TestNG.run(TestNG.java:1031)
	at org.apache.maven.surefire.testng.TestNGExecutor.run(TestNGExecutor.java:135)
	at org.apache.maven.surefire.testng.TestNGDirectoryTestSuite.executeMulti(TestNGDirectoryTestSuite.java:193)
	at org.apache.maven.surefire.testng.TestNGDirectoryTestSuite.execute(TestNGDirectoryTestSuite.java:94)
	at org.apache.maven.surefire.testng.TestNGProvider.invoke(TestNGProvider.java:146)
	at org.apache.maven.surefire.booter.ForkedBooter.invokeProviderInSameClassLoader(ForkedBooter.java:386)
	at org.apache.maven.surefire.booter.ForkedBooter.runSuitesInProcess(ForkedBooter.java:323)
	at org.apache.maven.surefire.booter.ForkedBooter.main(ForkedBooter.java:143)
]]>
            </full-stacktrace>
          </exception> <!-- java.lang.AssertionError -->
          <reporter-output>
          </reporter-output>
        </test-method> <!-- testAdd2 -->
      </class> <!-- AddTestIT -->
    </test> <!-- Surefire test -->
  </suite> <!-- Surefire suite -->
</testng-results>
